Workbook

Sheet FAPEU
A1: Nº | B1: Projeto | D1: Contratado | E1: Rec até | F1: A Receber | S1: Total a Receber
E2: 46173 | F2: 46174 | G2: 46204 | H2: 46235 | I2: 46266 | J2: 46296 | K2: 46327 | L2: 46357 | M2: 46388 | N2: 46419 | O2: 46447 | P2: 46478 | Q2: 46508 | R2: jun/27 a dez/28
A3: 1 | B3: 011/2024 | C3: SAC 2023 | D3: ='SAC 2024'!D67 | E3: ='SAC 2024'!E67 | F3: ='SAC 2024'!E2 | G3: ='SAC 2024'!F2 | H3: ='SAC 2024'!G2 | I3: ='SAC 2024'!H2 | J3: ='SAC 2024'!I2 | K3: ='SAC 2024'!J2 | L3: ='SAC 2024'!K2 | M3: ='SAC 2024'!L2 | ... Q3: ='SAC 2024'!P2 | R3: =SUM('SAC 2024'!R2:AI2) | S3: =SUM(F3:R3)
A4: =A3+1 | B4: 062/2024 | C4: Prodesp | D4: =Prodesp!D92 | E4: =Prodesp!E92 | F4: =Prodesp!E2 | G4: =Prodesp!F2 | H4: =Prodesp!G2 | I4: =Prodesp!H2 | J4: =Prodesp!I2 | K4: =Prodesp!J2 | L4: =Prodesp!K2 | M4: =Prodesp!L2 | ... P4: =Prodesp!O2 | S4: =SUM(F4:R4)
A5: =A4+1 | B5: 087/2024 | C5: DER-MG | D5: ='DER-MG'!D44 | E5: ='DER-MG'!E45 | F5: ='DER-MG'!E2 | G5: ='DER-MG'!F2 | H5: ='DER-MG'!G2 | I5: ='DER-MG'!H2 | J5: ='DER-MG'!I2 | K5: ='DER-MG'!J2 | L5: ='DER-MG'!K2 | M5: ='DER-MG'!L2 | ... O5: ='DER-MG'!N2 | S5: =SUM(F5:R5)
A6: =A5+1 | B6: 050/2025 | C6: SGG Goiás | D6: =Goiás!D36 | E6: =Goiás!E36 | F6: =Goiás!D2 | G6: =Goiás!E2 | H6: =Goiás!F2 | S6: =SUM(F6:R6)
A7: =A6+1 | B7: 114/2025 | C7: SAC BIM | D7: ='SAC BIM'!D136 | E7: ='SAC BIM'!E136 | F7: ='SAC BIM'!E2 | G7: ='SAC BIM'!F2 | H7: ='SAC BIM'!G2 | I7: ='SAC BIM'!H2 | J7: ='SAC BIM'!I2 | K7: ='SAC BIM'!J2 | L7: ='SAC BIM'!K2 | M7: ='SAC BIM'!L2 | ... Q7: ='SAC BIM'!P2 | R7: =SUM('SAC BIM'!Q2:BG2) | S7: =SUM(F7:R7)
A8: =A7+1 | B8: 014/2026 | C8: RUMO | D8: =RUMO!D29 | E8: =RUMO!E28 | F8: =RUMO!E2 | G8: =RUMO!F2 | H8: =RUMO!G2 | I8: =RUMO!H2 | J8: =RUMO!I2 | K8: =RUMO!J2 | L8: =RUMO!K2 | M8: =RUMO!L2 | ... Q8: =RUMO!P2 | R8: =SUM(RUMO!Q2:V2) | S8: =SUM(F8:R8)
A9: =A8+1 | B9: 015/2026 | C9: SGG Goiás II | D9: ='Goias II'!D27 | E9: ='Goias II'!D2 | F9: ='Goias II'!E2 | G9: ='Goias II'!F2 | H9: ='Goias II'!G2 | I9: ='Goias II'!H2 | J9: ='Goias II'!I2 | K9: ='Goias II'!J2 | L9: ='Goias II'!K2 | ... N9: ='Goias II'!M2 | S9: =SUM(F9:R9)
A10: =A9+1 | B10: xxx/2026 | C10: DNIT CGPERT | D10: ='DNIT 2026'!D102 | E10: ='DNIT 2026'!E102 | S10: =SUM(F10:R10)
A11: Totais Receitas | D11: =SUM(D3:D10) | E11: =SUM(E3:E10) | F11: =SUM(F3:F10) | G11: =SUM(G3:G10) | H11: =SUM(H3:H10) | I11: =SUM(I3:I10) | J11: =SUM(J3:J10) | K11: =SUM(K3:K10) | ... S11: =SUM(S3:S10)
A13: Nº | B13: Projeto | E13: Realizado até | F13: A Realizar | S13: Total a Realizar
E14: =E2 | F14: =F2 | G14: =G2 | H14: =H2 | I14: =I2 | J14: =J2 | K14: =K2 | L14: =L2 | ... R14: =R2
A15: 1 | B15: =B3 | C15: =C3 | E15: =-'SAC 2024'!G67 | F15: ='SAC 2024'!E55 | G15: ='SAC 2024'!F55 | H15: ='SAC 2024'!G55 | I15: ='SAC 2024'!H55 | J15: ='SAC 2024'!I55 | K15: ='SAC 2024'!J55 | L15: ='SAC 2024'!K55 | M15: ='SAC 2024'!L55 | ... Q15: ='SAC 2024'!P55 | R15: =SUM('SAC 2024'!Q55:AI55) | S15: =SUM(F15:R15)
A16: =A15+1 | B16: =B4 | C16: =C4 | E16: =-Prodesp!G93 | F16: =Prodesp!E87 | G16: =Prodesp!F87 | H16: =Prodesp!G87 | I16: =Prodesp!H87 | J16: =Prodesp!I87 | K16: =Prodesp!J87 | L16: =Prodesp!K87 | M16: =Prodesp!L87 | ... P16: =Prodesp!O87 | S16: =SUM(F16:R16)
A17: =A16+1 | B17: =B5 | C17: =C5 | E17: =-'DER-MG'!G45 | F17: ='DER-MG'!E39 | G17: ='DER-MG'!F39 | H17: ='DER-MG'!G39 | I17: ='DER-MG'!H39 | J17: ='DER-MG'!I39 | K17: ='DER-MG'!J39 | L17: ='DER-MG'!K39 | M17: ='DER-MG'!L39 | ... O17: ='DER-MG'!N39 | S17: =SUM(F17:R17)
A18: =A17+1 | B18: =B6 | C18: =C6 | E18: =-Goiás!G36 | F18: =Goiás!D23 | G18: =Goiás!E23 | H18: =Goiás!F23 | S18: =SUM(F18:R18)
A19: =A18+1 | B19: =B7 | C19: =C7 | E19: =-'SAC BIM'!G136 | F19: ='SAC BIM'!E124 | G19: ='SAC BIM'!F124 | H19: ='SAC BIM'!G124 | I19: ='SAC BIM'!H124 | J19: ='SAC BIM'!I124 | K19: ='SAC BIM'!J124 | L19: ='SAC BIM'!K124 | M19: ='SAC BIM'!L124 | ... Q19: ='SAC BIM'!P124 | R19: =SUM('SAC BIM'!Q124:BG124) | S19: =SUM(F19:R19)
A20: =A19+1 | B20: =B8 | C20: =C8 | E20: =-RUMO!G28 | F20: =RUMO!E23 | G20: =RUMO!F23 | H20: =RUMO!G23 | I20: =RUMO!H23 | J20: =RUMO!I23 | K20: =RUMO!J23 | L20: =RUMO!K23 | M20: =RUMO!L23 | ... Q20: =RUMO!P23 | R20: =SUM(RUMO!Q23:V23) | S20: =SUM(F20:R20)
A21: =A20+1 | B21: =B9 | C21: =C9 | E21: =-'Goias II'!G27 | F21: ='Goias II'!E22 | G21: ='Goias II'!F22 | H21: ='Goias II'!G22 | I21: ='Goias II'!H22 | J21: ='Goias II'!I22 | K21: ='Goias II'!J22 | L21: ='Goias II'!K22 | M21: ='Goias II'!L22 | N21: ='Goias II'!M22 | S21: =SUM(F21:R21)
A22: =A21+1 | B22: =B10 | C22: =C10 | E22: =-'DNIT 2026'!G102 | S22: =SUM(F22:R22)
A23: Totais Despesas | E23: =SUM(E15:E22) | F23: =SUM(F15:F22) | G23: =SUM(G15:G22) | H23: =SUM(H15:H22) | I23: =SUM(I15:I22) | J23: =SUM(J15:J22) | K23: =SUM(K15:K22) | L23: =SUM(L15:L22) | ... S23: =SUM(S15:S22)
A25: Nº | B25: Projeto | E25: Saldo Atual | F25: Saldo Projetado | S25: Total projetado
F26: =F14 | G26: =G14 | H26: =H14 | I26: =I14 | J26: =J14 | K26: =K14 | L26: =L14 | M26: =M14 | ... R26: =R14
A27: 1 | B27: =B15 | C27: =C15 | E27: ='SAC 2024'!D56 | F27: =E27+F3-F15 | G27: =F27+G3-G15 | H27: =G27+H3-H15 | I27: =H27+I3-I15 | J27: =I27+J3-J15 | K27: =J27+K3-K15 | L27: =K27+L3-L15 | M27: =L27+M3-M15 | ... R27: =Q27+R3-R15 | S27: =R27
A28: =A27+1 | B28: =B16 | C28: =C16 | E28: =Prodesp!D88 | F28: =E28+F4-F16 | G28: =F28+G4-G16 | H28: =G28+H4-H16 | I28: =H28+I4-I16 | J28: =I28+J4-J16 | K28: =J28+K4-K16 | L28: =K28+L4-L16 | M28: =L28+M4-M16 | ... P28: =O28+P4-P16 | S28: =P28
A29: =A28+1 | B29: =B17 | C29: =C17 | E29: ='DER-MG'!D40 | F29: =E29+F5-F17 | G29: =F29+G5-G17 | H29: =G29+H5-H17 | I29: =H29+I5-I17 | J29: =I29+J5-J17 | K29: =J29+K5-K17 | L29: =K29+L5-L17 | M29: =L29+M5-M17 | ... O29: =N29+O5-O17 | S29: =O29
A30: =A29+1 | B30: =B18 | C30: =C18 | E30: =Goiás!C24 | F30: =E30+F6-F18 | G30: =F30+G6-G18 | H30: =G30+H6-H18 | S30: =H30
A31: =A30+1 | B31: =B19 | C31: =C19 | E31: ='SAC BIM'!H136 | F31: =E31+F7-F19 | G31: =F31+G7-G19 | H31: =G31+H7-H19 | I31: =H31+I7-I19 | J31: =I31+J7-J19 | K31: =J31+K7-K19 | L31: =K31+L7-L19 | M31: =L31+M7-M19 | ... R31: =Q31+R7-R19 | S31: =R31
A32: =A31+1 | B32: =B20 | C32: =C20 | E32: =RUMO!D24 | F32: =E32+F8-F20 | G32: =F32+G8-G20 | H32: =G32+H8-H20 | I32: =H32+I8-I20 | J32: =I32+J8-J20 | K32: =J32+K8-K20 | L32: =K32+L8-L20 | M32: =L32+M8-M20 | ... R32: =Q32+R8-R20 | S32: =R32
A33: =A32+1 | B33: =B21 | C33: =C21 | E33: ='Goias II'!D23 | F33: =E33+F9-F21 | G33: =F33+G9-G21 | H33: =G33+H9-H21 | I33: =H33+I9-I21 | J33: =I33+J9-J21 | K33: =J33+K9-K21 | L33: =K33+L9-L21 | M33: =L33+M9-M21 | N33: =M33+N9-N21 | S33: =N33
A34: =A33+1 | B34: =B22 | C34: =C22 | E34: ='DNIT 2026'!D90 | F34: =E34+F10-F22 | G34: =F34+G10-G22 | H34: =G34+H10-H22 | I34: =H34+I10-I22 | J34: =I34+J10-J22 | K34: =J34+K10-K22 | L34: =K34+L10-L22 | M34: =L34+M10-M22 | ... R34: =Q34+R10-R22 | S34: =R34
A35: Saldos dos Projetos | E35: =SUM(E27:E34) | F35: =SUM(F27:F34) | G35: =SUM(G27:G34) | H35: =SUM(H27:H34) | I35: =SUM(I27:I34) | J35: =SUM(J27:J34) | K35: =SUM(K27:K34) | L35: =SUM(L27:L34) | ... S35: =SUM(S27:S34)
A36: =A30+1 | B36: 999/9999 | C36: Provisões
A37: Saldo Total na Fundação | E37: =SUM(E35:E36) | F37: =SUM(F35:F36) | G37: =SUM(G35:G36) | H37: =SUM(H35:H36) | I37: =SUM(I35:I36) | J37: =SUM(J35:J36) | K37: =SUM(K35:K36) | L37: =SUM(L35:L36) | ... S37: =SUM(S35:S36)

Sheet FabioMattos
A1: Categorias Finaceiras | D1: Log de Cáculo
A2: Código | B2: Descrição
A3: 1 | B3: Reembolso | D3: Receita | E3: Categorias | F3: 15.55
A4: 2 | B4: Suprimento de fundos | D4: Despesas | E4: Categora Diferente | F4: 18
A5: 3 | B5: Adiantamento para viagens | D5: Clt | E5: Detalhamento Folha | F5: Formula | G5: CUSTO_PROJETO = (VALOR_PROVENTO + VALOR_BENEFICIO + VALOR_ENCARGO + VALOR_PROVISAO) - ESTORNO
A6: 4 | B6: Diarias CLT | D6: PessoalNaoContatado | E6: Categorias | F6: 6,10,11
A7: 5 | B7: Pessoa Jurídica - NF de VENDAS | D7: Redoa | E7: Categorias | F7: 26
A8: 6 | B8: Bolsa de estágio
A9: 7 | B9: Diárias Pessoal Sem Vínculo Empregatício | D9: Sql Consulta
A10: 8 | B10: Impostos e Contribuições PJ
A11: 9 | B11: Impostos Pessoal Sem Vínculo Empregatício - RPA | D11: WITH RECEITA AS
A12: 10 | B12: Pessoal sem Vínculo Empregatício - RPA | D12: (
A13: 11 | B13: Bolsas | D13: SELECT
A14: 12 | B14: Transferencia entre Contas | D14: LR.IDProjetoRateio,
A15: 13 | B15: Pessoa Fisica - ALUGUEL | D15: SUM(LR.ValorRateio) AS TotalReceita
A16: 14 | B16: Pessoa Contratado Celetista - CLT | D16: FROM TBLancamento L (NOLOCK)
A17: 15 | B17: Receita | D17: INNER JOIN TBLancamentoRateio LR (NOLOCK)
A18: 16 | B18: Despesas Bancárias | D18: ON LR.IDLancamentoRateio = L.IDLancamento
A19: 17 | B19: Ajuste de Saldo Inicial | D19: INNER JOIN TBProjeto P (NOLOCK)
A20: 18 | B20: Aplicação Financeira | D20: ON P.IDProjeto = LR.IDProjetoRateio
A21: 19 | B21: Devolução de Cheque | D21: WHERE L.IDCategoriaFinanceira in(15,55)
A22: 20 | B22: Devolução Recebida | D22: AND P.CodigoProjetoCompleto IN ('112024','622024','872024','502025','1142025','142026','152026')
... A67: 69 | B67: Transferência de Saldo de cutro prazo para longo prazo | D67: AND P.CodigoProjetoCompleto IN ('112024','622024','872024','502025','1142025','142026','152026')
D68: AND L.Data > 0
D69: GROUP BY LR.IDProjetoRateio
D70: ),
D71: DESPESAS AS
D72: (
D73: SELECT
D74: LR.IDProjetoRateio,
D75: SUM(LR.ValorRateio) AS TotalDespesas
D76: FROM TBLancamento L (NOLOCK)
D77: INNER JOIN TBLancamentoRateio LR (NOLOCK) ON LR.IDLancamentoRateio = L.IDLancamento
D78: INNER JOIN TBProjeto P (NOLOCK) ON P.IDProjeto = LR.IDProjetoRateio
D79: INNER JOIN tbcategoriafinanceira tbcategoriafinanceira (NOLOCK) ON tbcategoriafinanceira.IDCategoriaFinanceira = L.IDCategoriaFinanceira
... D106: ORDER BY P.CodigoProjetoCompleto;

Sheet saldoFAPEU
A1: cdProjeto | B1: PRJ | C1: TotalReceita | D1: TotalDespesas | E1: TotalCLT | F1: TotalPessoalNaoContratado | G1: TotalRedoa
A2: 112024 | B2: 2024.011 | C2: 37371852 | D2: 40809976 | E2: 27618823 | F2: 3022277.6 | G2: 2821574.8
A3: 1142025 | B3: 2025.114 | C3: 25200000 | D3: 9614566.6 | E3: 4604998.8 | F3: 456194.92 | G3: 1902600
A4: 142026 | B4: 2026.014 | C4: 330031 | D4: 281218.77 | E4: 166922.22 | F4: 43619.5 | G4: 24592.25
A5: 502025 | B5: 2025.050 | C5: 1989653 | D5: 1645034.7 | E5: 216680.51 | F5: 303083.46 | G5: 198965.3
A6: 622024 | B6: 2024.062 | C6: 14412319 | D6: 19260999 | E6: 15834735 | F6: 360237.76 | G6: 1191898.8
A7: 872024 | B7: 2024.087 | C7: 3116712.2 | D7: 4474028.8 | E7: 2914812.1 | F7: 275856.17 | G7: 257128.76

Sheet saldo fapeu
B2: Receitas | C2: Despesas
A3: 011/2024 | B3: 32902922 | C3: 40934160
A4: 062/2024 | B4: 11912464 | C4: 19520464 | E4: Excluir empréstimo
A5: 087/2024 | B5: 3016712.2 | C5: 4699312.2 | E5: Excluir aplicação
A6: 050/2025 | B6: 1989653 | C6: 2464282.9 | E6: incluir o rendimento de aplicação
A7: 114/2025 | B7: 25200000 | C7: 10271238
A8: 014/2026 | B8: 330031 | C8: 261157.66
A9: 015/2026 | B9: 0 | C9: 0

Sheet Análise
B2: Análise por projeto
B4: Número do Projeto | C4: 014/2026 | F4: =VLOOKUP(C4,FAPEU!B3:C10,2,0)
B7: Valor contratado | C7: =VLOOKUP(C4,FAPEU!B3:D10,3,0) | K7: Análise mensal | M7: 46419
B9: Recebido (Projeto) | C9: =VLOOKUP(C4,FAPEU!B3:E10,4,0) | E9: =C9/C7 | K9: Recebimento | M9: =VLOOKUP(C4,FAPEU!B3:R10,D31,0)
B10: Recebimento - Fapeu | C10: =VLOOKUP(C4,'saldo fapeu'!A3:B9,2,0) | E10: =C10/C7 | K10: Despesas programadas | M10: =VLOOKUP(C4,FAPEU!B15:R22,D31,0)
K11: Saldo projetado | M11: =VLOOKUP(C4,FAPEU!B27:R34,Análise!D31,0)
B12: À receber (Projeto) | C12: =C7-C9 | E12: =C12/C7
B13: À Receber FAPEU | C13: =C7-C10 | E13: =C13/C7 | K13: =MATCH(K14,FAPEU!$B$2:$R$2,0) | L13: =MATCH(L14,FAPEU!$B$2:$R$2,0) | M13: =MATCH(M14,FAPEU!$B$2:$R$2,0) | N13: =MATCH(N14,FAPEU!$B$2:$R$2,0) | O13: =MATCH(O14,FAPEU!$B$2:$R$2,0) | P13: =MATCH(P14,FAPEU!$B$2:$R$2,0) | Q13: =MATCH(Q14,FAPEU!$B$2:$R$2,0) | R13: =MATCH(R14,FAPEU!$B$2:$R$2,0) | ... W13: =MATCH(W14,FAPEU!$B$2:$R$2,0)
K14: 46174 | L14: 46204 | M14: 46235 | N14: 46266 | O14: 46296 | P14: 46327 | Q14: 46357 | R14: 46388 | S14: 46419 | T14: 46447 | U14: 46478 | V14: 46508 | W14: jun/27 a dez/28
B15: Gastos realizados (Projeto) | C15: =VLOOKUP(C4,FAPEU!B15:E22,4,0) | E15: =C15/C7 | I15: Entradas | K15: =VLOOKUP($C$4,FAPEU!$B$3:$R$10,K13,0) | L15: =VLOOKUP($C$4,FAPEU!$B$3:$R$10,L13,0) | M15: =VLOOKUP($C$4,FAPEU!$B$3:$R$10,M13,0) | N15: =VLOOKUP($C$4,FAPEU!$B$3:$R$10,N13,0) | O15: =VLOOKUP($C$4,FAPEU!$B$3:$R$10,O13,0) | P15: =VLOOKUP($C$4,FAPEU!$B$3:$R$10,P13,0) | Q15: =VLOOKUP($C$4,FAPEU!$B$3:$R$10,Q13,0) | R15: =VLOOKUP($C$4,FAPEU!$B$3:$R$10,R13,0) | ... W15: =VLOOKUP($C$4,FAPEU!$B$3:$R$10,W13,0)
B16: Gastos Realizado - Fapeu | C16: =VLOOKUP(C4,'saldo fapeu'!A3:C9,3,0) | E16: =C16/C7 | I16: Saídas | K16: =VLOOKUP($C$4,FAPEU!$B$15:$R$22,K13,0) | L16: =VLOOKUP($C$4,FAPEU!$B$15:$R$22,L13,0) | M16: =VLOOKUP($C$4,FAPEU!$B$15:$R$22,M13,0) | N16: =VLOOKUP($C$4,FAPEU!$B$15:$R$22,N13,0) | O16: =VLOOKUP($C$4,FAPEU!$B$15:$R$22,O13,0) | P16: =VLOOKUP($C$4,FAPEU!$B$15:$R$22,P13,0) | Q16: =VLOOKUP($C$4,FAPEU!$B$15:$R$22,Q13,0) | R16: =VLOOKUP($C$4,FAPEU!$B$15:$R$22,R13,0) | ... W16: =VLOOKUP($C$4,FAPEU!$B$15:$R$22,W13,0)
I17: Saldo | K17: =VLOOKUP($C$4,FAPEU!$B$27:$R$34,K13,0) | L17: =VLOOKUP($C$4,FAPEU!$B$27:$R$34,L13,0) | M17: =VLOOKUP($C$4,FAPEU!$B$27:$R$34,M13,0) | N17: =VLOOKUP($C$4,FAPEU!$B$27:$R$34,N13,0) | O17: =VLOOKUP($C$4,FAPEU!$B$27:$R$34,O13,0) | P17: =VLOOKUP($C$4,FAPEU!$B$27:$R$34,P13,0) | Q17: =VLOOKUP($C$4,FAPEU!$B$27:$R$34,Q13,0) | R17: =VLOOKUP($C$4,FAPEU!$B$27:$R$34,R13,0) | ... W17: =VLOOKUP($C$4,FAPEU!$B$27:$R$34,W13,0)
B18: Saldo financeiro projeto | C18: =C9-C15 | E18: =C18/C7
B19: Saldo Financeiro Fapeu | C19: =C10-C16 | E19: =C19/C7
B21: Saldo Restante (Projeto) | C21: =C7-C15 | E21: =C21/C7
B22: Saldo Restante Fapeu | C22: =C7-C16 | E22: =C22/C7
B24: Gastos programados (Projeto) | C24: =VLOOKUP(C4,FAPEU!B15:S22,18,0) | E24: =C24/C7
B26: Resultado Previsto (Projeto) | C26: =C9+C12-C15-C24 | E26: =C26/C7
B27: Resultado Previsto FAPEU | C27: =C10+C13-C16-C24 | E27: =C27/C7
D31: =MATCH(M7,FAPEU!B2:R2,0)

Sheet SAC 2024
A1: N˚ | B1: Receita | D1: Até mai/26 | E1: 46174 | F1: 46204 | G1: 46235 | H1: 46266 | I1: 46296 | J1: 46327 | K1: 46357 | L1: 46388 | M1: 46419 | N1: 46447 | O1: 46478 | P1: 46508 | Q1: 46539 | R1: 46569 | S1: 46600 | T1: 46631 | U1: 46661 | V1: 46692 | W1: 46722 | X1: 46753 | Y1: 46784 | Z1: 46813 | AA1: 46844 | AB1: 46874 | AC1: 46905 | AD1: 46935 | AE1: 46966 | AF1: 46997 | AG1: 47027 | AH1: 47058 | AI1: 47088 | AJ1: Totais
A2: 1 | B2: Parcelas | D2: =E67 | E2: 3468930 | F2: 0 | G2: 3468930 | H2: 0 | I2: 0 | J2: 0 | K2: 3468930 | L2: 0 | M2: 0 | N2: 0 | O2: 3468930 | P2: 0 | Q2: 0 | R2: 0 | S2: 3468930 | T2: 0 | U2: 0 | V2: 0 | W2: 3468930 | X2: 0 | Y2: 0 | Z2: 0 | AA2: 2914837 | AB2: 0 | AC2: 0 | AD2: 0 | AE2: 2360744 | AF2: 0 | AG2: 0 | AH2: 0 | AI2: 0 | AJ2: =SUM(D2:AI2)
A3: N˚ | B3: Despesas | E3: =E1 | F3: =F1 | G3: =G1 | H3: =H1 | I3: =I1 | J3: =J1 | K3: =K1 | L3: =L1 | ... AI3: =AI1 | AJ3: Totais
A4: 1 | B4: Alexandre Royes Schardosim | E4: 4174.4 | F4: 4174.4 | G4: 4174.4 | H4: 4174.4 | I4: 4174.4 | J4: 4174.4 | K4: 4174.4 | L4: 4174.4 | M4: 4174.4 | N4: =M4*1.05 | O4: =N4 | P4: =O4 | Q4: =P4 | R4: =Q4 | S4: =R4 | T4: =S4 | U4: =T4 | V4: =U4 | ... Y4: =X4 | Z4: =Y4*1.05 | AA4: =Z4 | AB4: =AA4 | AC4: =AB4 | AD4: =AC4 | AE4: =AD4 | AF4: =AE4 | AG4: =AF4 | AH4: =AG4 | AI4: =AH4 | AJ4: =SUM(E4:AI4)
A5: =A4+1 | B5: André Luis Fernandes do Espirito Santo | E5: 3830.48 | F5: 3830.48 | G5: 3830.48 | H5: 3830.48 | I5: 3830.48 | J5: 3830.48 | K5: 3830.48 | L5: 3830.48 | M5: 3830.48 | N5: =M5*1.05 | O5: =N5 | P5: =O5 | Q5: =P5 | R5: =Q5 | S5: =R5 | T5: =S5 | U5: =T5 | V5: =U5 | ... Y5: =X5 | Z5: =Y5*1.05 | AA5: =Z5 | AB5: =AA5 | AC5: =AB5 | AD5: =AC5 | AE5: =AD5 | AF5: =AE5 | AG5: =AF5 | AH5: =AG5 | AI5: =AH5 | AJ5: =SUM(E5:AI5)
A6: =A5+1 | B6: Bernardo Victor Engelke | E6: =9224.22+553.45 | F6: =9224.22+553.45 | G6: =9224.22+553.45 | H6: =9224.22+553.45 | I6: =9224.22+553.45 | J6: =9224.22+553.45 | K6: =9224.22+553.45 | L6: =9224.22+553.45 | M6: =9224.22+553.45 | N6: =M6*1.05 | O6: =N6 | P6: =O6 | Q6: =P6 | R6: =Q6 | S6: =R6 | T6: =S6 | U6: =T6 | V6: =U6 | ... Y6: =X6 | Z6: =Y6*1.05 | AA6: =Z6 | AB6: =AA6 | AC6: =AB6 | AD6: =AC6 | AE6: =AD6 | AF6: =AE6 | AG6: =AF6 | AH6: =AG6 | AI6: =AH6 | AJ6: =SUM(E6:AI6)
A7: =A6+1 | B7: Caroline Bettini Frison | E7: 11709.19 | F7: 11709.19 | G7: 11709.19 | H7: 11709.19 | I7: 11709.19 | J7: 11709.19 | K7: 11709.19 | L7: 11709.19 | M7: 11709.19 | N7: =M7*1.05 | O7: =N7 | P7: =O7 | Q7: =P7 | R7: =Q7 | S7: =R7 | T7: =S7 | U7: =T7 | V7: =U7 | ... Y7: =X7 | Z7: =Y7*1.05 | AA7: =Z7 | AB7: =AA7 | AC7: =AB7 | AD7: =AC7 | AE7: =AD7 | AF7: =AE7 | AG7: =AF7 | AH7: =AG7 | AI7: =AH7 | AJ7: =SUM(E7:AI7)
A8: =A7+1 | B8: César Augusto Pereira de Souza | E8: 4800 | F8: 4800 | G8: 4800 | H8: 4800 | I8: 4800 | J8: 4800 | K8: 4800 | L8: 4800 | M8: 4800 | N8: =M8*1.05 | O8: =N8 | P8: =O8 | Q8: =P8 | R8: =Q8 | S8: =R8 | T8: =S8 | U8: =T8 | V8: =U8 | ... Y8: =X8 | Z8: =Y8*1.05 | AA8: =Z8 | AB8: =AA8 | AC8: =AB8 | AD8: =AC8 | AE8: =AD8 | AF8: =AE8 | AG8: =AF8 | AH8: =AG8 | AI8: =AH8 | AJ8: =SUM(E8:AI8)
A9: =A8+1 | B9: Gabriel da Costa Cardoso | E9: 3391.7 | F9: 3391.7 | G9: 3391.7 | H9: 3391.7 | I9: 3391.7 | J9: 3391.7 | K9: 3391.7 | L9: 3391.7 | M9: 3391.7 | N9: =M9*1.05 | O9: =N9 | P9: =O9 | Q9: =P9 | R9: =Q9 | S9: =R9 | T9: =S9 | U9: =T9 | V9: =U9 | ... Y9: =X9 | Z9: =Y9*1.05 | AA9: =Z9 | AB9: =AA9 | AC9: =AB9 | AD9: =AC9 | AE9: =AD9 | AF9: =AE9 | AG9: =AF9 | AH9: =AG9 | AI9: =AH9 | AJ9: =SUM(E9:AI9)
A10: =A9+1 | B10: Guilherme Henrique Correia Sena | E10: =8400.25+252.01 | F10: =8400.25+252.01 | G10: =8400.25+252.01 | H10: =8400.25+252.01 | I10: =8400.25+252.01 | J10: =8400.25+252.01 | K10: =8400.25+252.01 | L10: =8400.25+252.01 | M10: =8400.25+252.01 | N10: =M10*1.05 | O10: =N10 | P10: =O10 | Q10: =P10 | R10: =Q10 | S10: =R10 | T10: =S10 | U10: =T10 | V10: =U10 | ... Y10: =X10 | Z10: =Y10*1.05 | AA10: =Z10 | AB10: =AA10 | AC10: =AB10 | AD10: =AC10 | AE10: =AD10 | AF10: =AE10 | AG10: =AF10 | AH10: =AG10 | AI10: =AH10 | AJ10: =SUM(E10:AI10)
A11: =A10+1 | B11: Helena Spaniol | E11: =7705.43+462.33 | F11: =7705.43+462.33 | G11: =7705.43+462.33 | H11: =7705.43+462.33 | I11: =7705.43+462.33 | J11: =7705.43+462.33 | K11: =7705.43+462.33 | L11: =7705.43+462.33 | M11: =7705.43+462.33 | N11: =M11*1.05 | O11: =N11 | P11: =O11 | Q11: =P11 | R11: =Q11 | S11: =R11 | T11: =S11 | U11: =T11 | V11: =U11 | ... Y11: =X11 | Z11: =Y11*1.05 | AA11: =Z11 | AB11: =AA11 | AC11: =AB11 | AD11: =AC11 | AE11: =AD11 | AF11: =AE11 | AG11: =AF11 | AH11: =AG11 | AI11: =AH11 | AJ11: =SUM(E11:AI11)
A12: =A11+1 | B12: João Vitor Ferreira Pedro | E12: =4377.69 | F12: =4377.69 | G12: =4377.69 | H12: =4377.69 | I12: =4377.69 | J12: =4377.69 | K12: =4377.69 | L12: =4377.69 | M12: =4377.69 | N12: =M12*1.05 | O12: =N12 | P12: =O12 | Q12: =P12 | R12: =Q12 | S12: =R12 | T12: =S12 | U12: =T12 | V12: =U12 | ... Y12: =X12 | Z12: =Y12*1.05 | AA12: =Z12 | AB12: =AA12 | AC12: =AB12 | AD12: =AC12 | AE12: =AD12 | AF12: =AE12 | AG12: =AF12 | AH12: =AG12 | AI12: =AH12 | AJ12: =SUM(E12:AI12)
A13: =A12+1 | B13: Julia Bronzatti Jochims | E13: 6261.6 | F13: 6261.6 | G13: 6261.6 | H13: 6261.6 | I13: 6261.6 | J13: 6261.6 | K13: 6261.6 | L13: 6261.6 | M13: 6261.6 | N13: =M13*1.05 | O13: =N13 | P13: =O13 | Q13: =P13 | R13: =Q13 | S13: =R13 | T13: =S13 | U13: =T13 | V13: =U13 | ... Y13: =X13 | Z13: =Y13*1.05 | AA13: =Z13 | AB13: =AA13 | AC13: =AB13 | AD13: =AC13 | AE13: =AD13 | AF13: =AE13 | AG13: =AF13 | AH13: =AG13 | AI13: =AH13 | AJ13: =SUM(E13:AI13)
A14: =A13+1 | B14: Julia Carmen Damiani Florentino | E14: =7046.3+422.78 | F14: =7046.3+422.78 | G14: =7046.3+422.78 | H14: =7046.3+422.78 | I14: =7046.3+422.78 | J14: =7046.3+422.78 | K14: =7046.3+422.78 | L14: =7046.3+422.78 | M14: =7046.3+422.78 | N14: =M14*1.05 | O14: =N14 | P14: =O14 | Q14: =P14 | R14: =Q14 | S14: =R14 | T14: =S14 | U14: =T14 | V14: =U14 | ... Y14: =X14 | Z14: =Y14*1.05 | AA14: =Z14 | AB14: =AA14 | AC14: =AB14 | AD14: =AC14 | AE14: =AD14 | AF14: =AE14 | AG14: =AF14 | AH14: =AG14 | AI14: =AH14 | AJ14: =SUM(E14:AI14)
A15: =A14+1 | B15: Karine Domingos | E15: =6019.33 | F15: =6019.33 | G15: =6019.33 | H15: =6019.33 | I15: =6019.33 | J15: =6019.33 | K15: =6019.33 | L15: =6019.33 | M15: =6019.33 | N15: =M15*1.05 | O15: =N15 | P15: =O15 | Q15: =P15 | R15: =Q15 | S15: =R15 | T15: =S15 | U15: =T15 | V15: =U15 | ... Y15: =X15 | Z15: =Y15*1.05 | AA15: =Z15 | AB15: =AA15 | AC15: =AB15 | AD15: =AC15 | AE15: =AD15 | AF15: =AE15 | AG15: =AF15 | AH15: =AG15 | AI15: =AH15 | AJ15: =SUM(E15:AI15)
A16: =A15+1 | B16: Leandro Quingerski | E16: =17446.25+1570.16 | F16: =17446.25+1570.16 | G16: =17446.25+1570.16 | H16: =17446.25+1570.16 | I16: =17446.25+1570.16 | J16: =17446.25+1570.16 | K16: =17446.25+1570.16 | L16: =17446.25+1570.16 | M16: =17446.25+1570.16 | N16: =M16*1.05 | O16: =N16 | P16: =O16 | Q16: =P16 | R16: =Q16 | S16: =R16 | T16: =S16 | U16: =T16 | V16: =U16 | ... Y16: =X16 | Z16: =Y16*1.05 | AA16: =Z16 | AB16: =AA16 | AC16: =AB16 | AD16: =AC16 | AE16: =AD16 | AF16: =AE16 | AG16: =AF16 | AH16: =AG16 | AI16: =AH16 | AJ16: =SUM(E16:AI16)
A17: =A16+1 | B17: Lucas Oliveira Pereira da Silva | E17: 5472.12 | F17: 5472.12 | G17: 5472.12 | H17: 5472.12 | I17: 5472.12 | J17: 5472.12 | K17: 5472.12 | L17: 5472.12 | M17: 5472.12 | N17: =M17*1.05 | O17: =N17 | P17: =O17 | Q17: =P17 | R17: =Q17 | S17: =R17 | T17: =S17 | U17: =T17 | V17: =U17 | ... Y17: =X17 | Z17: =Y17*1.05 | AA17: =Z17 | AB17: =AA17 | AC17: =AB17 | AD17: =AC17 | AE17: =AD17 | AF17: =AE17 | AG17: =AF17 | AH17: =AG17 | AI17: =AH17 | AJ17: =SUM(E17:AI17)
A18: =A17+1 | B18: Luciano Vecchi Biolo | E18: 5894.25 | F18: 5894.25 | G18: 5894.25 | H18: 5894.25 | I18: 5894.25 | J18: 5894.25 | K18: 5894.25 | L18: 5894.25 | M18: 5894.25 | N18: =M18*1.05 | O18: =N18 | P18: =O18 | Q18: =P18 | R18: =Q18 | S18: =R18 | T18: =S18 | U18: =T18 | V18: =U18 | ... Y18: =X18 | Z18: =Y18*1.05 | AA18: =Z18 | AB18: =AA18 | AC18: =AB18 | AD18: =AC18 | AE18: =AD18 | AF18: =AE18 | AG18: =AF18 | AH18: =AG18 | AI18: =AH18 | AJ18: =SUM(E18:AI18)
A19: =A18+1 | B19: Luisandro Nachtigal Bandeira | E19: =13341.57+1200.74 | F19: =13341.57+1200.74 | G19: =13341.57+1200.74 | H19: =13341.57+1200.74 | I19: =13341.57+1200.74 | J19: =13341.57+1200.74 | K19: =13341.57+1200.74 | L19: =13341.57+1200.74 | M19: =13341.57+1200.74 | N19: =M19*1.05 | O19: =N19 | P19: =O19 | Q19: =P19 | R19: =Q19 | S19: =R19 | T19: =S19 | U19: =T19 | V19: =U19 | ... Y19: =X19 | Z19: =Y19*1.05 | AA19: =Z19 | AB19: =AA19 | AC19: =AB19 | AD19: =AC19 | AE19: =AD19 | AF19: =AE19 | AG19: =AF19 | AH19: =AG19 | AI19: =AH19 | AJ19: =SUM(E19:AI19)
A20: =A19+1 | B20: Patricia Royes Schardosin | E20: =6015.01+541.35 | F20: =6015.01+541.35 | G20: =6015.01+541.35 | H20: =6015.01+541.35 | I20: =6015.01+541.35 | J20: =6015.01+541.35 | K20: =6015.01+541.35 | L20: =6015.01+541.35 | M20: =6015.01+541.35 | N20: =M20*1.05 | O20: =N20 | P20: =O20 | Q20: =P20 | R20: =Q20 | S20: =R20 | T20: =S20 | U20: =T20 | V20: =U20 | ... Y20: =X20 | Z20: =Y20*1.05 | AA20: =Z20 | AB20: =AA20 | AC20: =AB20 | AD20: =AC20 | AE20: =AD20 | AF20: =AE20 | AG20: =AF20 | AH20: =AG20 | AI20: =AH20 | AJ20: =SUM(E20:AI20)
A21: =A20+1 | B21: Paula Carolina Ribeiro | E21: =11430.05+685.8 | F21: =11430.05+685.8 | G21: =11430.05+685.8 | H21: =11430.05+685.8 | I21: =11430.05+685.8 | J21: =11430.05+685.8 | K21: =11430.05+685.8 | L21: =11430.05+685.8 | M21: =11430.05+685.8 | N21: =M21*1.05 | O21: =N21 | P21: =O21 | Q21: =P21 | R21: =Q21 | S21: =R21 | T21: =S21 | U21: =T21 | V21: =U21 | ... Y21: =X21 | Z21: =Y21*1.05 | AA21: =Z21 | AB21: =AA21 | AC21: =AB21 | AD21: =AC21 | AE21: =AD21 | AF21: =AE21 | AG21: =AF21 | AH21: =AG21 | AI21: =AH21 | AJ21: =SUM(E21:AI21)
A22: =A21+1 | B22: Renan Ferreira Renzo | E22: =5472.12 | F22: =5472.12 | G22: =5472.12 | H22: =5472.12 | I22: =5472.12 | J22: =5472.12 | K22: =5472.12 | L22: =5472.12 | M22: =5472.12 | N22: =M22*1.05 | O22: =N22 | P22: =O22 | Q22: =P22 | R22: =Q22 | S22: =R22 | T22: =S22 | U22: =T22 | V22: =U22 | ... Y22: =X22 | Z22: =Y22*1.05 | AA22: =Z22 | AB22: =AA22 | AC22: =AB22 | AD22: =AC22 | AE22: =AD22 | AF22: =AE22 | AG22: =AF22 | AH22: =AG22 | AI22: =AH22 | AJ22: =SUM(E22:AI22)
A23: =A22+1 | B23: Renata Bruckmann Gomes Machado | E23: =8903.28+267.1 | F23: =8903.28+267.1 | G23: =8903.28+267.1 | H23: =8903.28+267.1 | I23: =8903.28+267.1 | J23: =8903.28+267.1 | K23: =8903.28+267.1 | L23: =8903.28+267.1 | M23: =8903.28+267.1 | N23: =M23*1.05 | O23: =N23 | P23: =O23 | Q23: =P23 | R23: =Q23 | S23: =R23 | T23: =S23 | U23: =T23 | V23: =U23 | ... Y23: =X23 | Z23: =Y23*1.05 | AA23: =Z23 | AB23: =AA23 | AC23: =AB23 | AD23: =AC23 | AE23: =AD23 | AF23: =AE23 | AG23: =AF23 | AH23: =AG23 | AI23: =AH23 | AJ23: =SUM(E23:AI23)
A24: =A23+1 | B24: Ricardo da Cunha Pereira | E24: =13778.5+413.36 | F24: =13778.5+413.36 | G24: =13778.5+413.36 | H24: =13778.5+413.36 | I24: =13778.5+413.36 | J24: =13778.5+413.36 | K24: =13778.5+413.36 | L24: =13778.5+413.36 | M24: =13778.5+413.36 | N24: =M24*1.05 | O24: =N24 | P24: =O24 | Q24: =P24 | R24: =Q24 | S24: =R24 | T24: =S24 | U24: =T24 | V24: =U24 | ... Y24: =X24 | Z24: =Y24*1.05 | AA24: =Z24 | AB24: =AA24 | AC24: =AB24 | AD24: =AC24 | AE24: =AD24 | AF24: =AE24 | AG24: =AF24 | AH24: =AG24 | AI24: =AH24 | AJ24: =SUM(E24:AI24)
A25: =A24+1 | B25: Victor Lima Costa | E25: 7305.2 | F25: 7305.2 | G25: 7305.2 | H25: 7305.2 | I25: 7305.2 | J25: 7305.2 | K25: 7305.2 | L25: 7305.2 | M25: 7305.2 | N25: =M25*1.05 | O25: =N25 | P25: =O25 | Q25: =P25 | R25: =Q25 | S25: =R25 | T25: =S25 | U25: =T25 | V25: =U25 | ... Y25: =X25 | Z25: =Y25*1.05 | AA25: =Z25 | AB25: =AA25 | AC25: =AB25 | AD25: =AC25 | AE25: =AD25 | AF25: =AE25 | AG25: =AF25 | AH25: =AG25 | AI25: =AH25 | AJ25: =SUM(E25:AI25)
A26: =A25+1 | B26: Vitor Motoaki Yabiku | E26: =11495.69+689.74 | F26: =11495.69+689.74 | G26: =11495.69+689.74 | H26: =11495.69+689.74 | I26: =11495.69+689.74 | J26: =11495.69+689.74 | K26: =11495.69+689.74 | L26: =11495.69+689.74 | M26: =11495.69+689.74 | N26: =M26*1.05 | O26: =N26 | P26: =O26 | Q26: =P26 | R26: =Q26 | S26: =R26 | T26: =S26 | U26: =T26 | V26: =U26 | ... Y26: =X26 | Z26: =Y26*1.05 | AA26: =Z26 | AB26: =AA26 | AC26: =AB26 | AD26: =AC26 | AE26: =AD26 | AF26: =AE26 | AG26: =AF26 | AH26: =AG26 | AI26: =AH26 | AJ26: =SUM(E26:AI26)
A27: =A26+1 | B27: Encargos Trabalhistas | E27: =(SUM(E4:E26)*0.8) | F27: =(SUM(F4:F26)*0.8) | G27: =(SUM(G4:G26)*0.8) | H27: =(SUM(H4:H26)*0.8) | I27: =(SUM(I4:I26)*0.8) | J27: =(SUM(J4:J26)*0.8) | K27: =(SUM(K4:K26)*0.8) | L27: =(SUM(L4:L26)*0.8) | ... AI27: =(SUM(AI4:AI26)*0.8) | AJ27: =SUM(E27:AI27) | BK27: 5236091 | BL27: =AJ27-BK27
A28: =A27+1 | B28: Alana Piccoli de Mello Correa | E28: 1050 | F28: 1050 | G28: 1050 | H28: 1050 | I28: 1050 | J28: 1050 | K28: 1050 | L28: 1050 | M28: 1050 | N28: 1050 | O28: 1050 | P28: 1050 | Q28: 1050 | R28: 1050 | S28: 1050 | T28: 1050 | U28: 1050 | V28: 1050 | W28: 1050 | X28: 1050 | Y28: 1050 | Z28: 1050 | AA28: 1050 | AJ28: =SUM(E28:AI28)
A29: =A28+1 | B29: Eduarda Vieira Florindo Tinoco | E29: 2200 | F29: 2200 | G29: 2200 | H29: 2200 | I29: 2200 | J29: 2200 | K29: 2200 | L29: 2200 | M29: 2200 | N29: 2200 | O29: 2200 | P29: 2200 | Q29: 2200 | R29: 2200 | S29: 2200 | T29: 2200 | U29: 2200 | V29: 2200 | W29: 2200 | X29: 2200 | Y29: 2200 | Z29: 2200 | AA29: 2200 | AB29: 2200 | AC29: 2200 | AD29: 2200 | AE29: 2200 | AF29: 2200 | AG29: 2200 | AH29: 2200 | AJ29: =SUM(E29:AI29)
A30: =A29+1 | B30: Eduardo Lobo | E30: 3000 | AJ30: =SUM(E30:AI30)
A31: =A30+1 | B31: Fernando Seabra | E31: 3000 | F31: 3000 | G31: 3000 | H31: 3000 | I31: 3000 | J31: 3000 | K31: 3000 | L31: 3000 | M31: 3000 | N31: 3000 | O31: 3000 | P31: 3000 | Q31: 3000 | R31: 3000 | S31: 3000 | T31: 3000 | U31: 3000 | V31: 3000 | W31: 3000 | X31: 3000 | Y31: 3000 | Z31: 3000 | AA31: 3000 | AJ31: =SUM(E31:AI31)
A32: =A31+1 | B32: Germano dos Reis Rivera | E32: 1050 | F32: 1050 | G32: 1050 | H32: 1050 | I32: 1050 | J32: 1050 | K32: 1050 | L32: 1050 | M32: 1050 | AJ32: =SUM(E32:AI32)
A33: =A32+1 | B33: Giulia Kaminski | E33: 1050 | F33: 1050 | G33: 1050 | H33: 1050 | I33: 1050 | J33: 1050 | K33: 1050 | L33: 1050 | M33: 1050 | AJ33: =SUM(E33:AI33)
A34: =A33+1 | B34: Isadora da Silva Cardoso | E34: 1050 | F34: 1050 | G34: 1050 | H34: 1050 | I34: 1050 | J34: 1050 | K34: 1050 | L34: 1050 | M34: 1050 | N34: 1050 | O34: 1050 | P34: 1050 | Q34: 1050 | R34: 1050 | S34: 1050 | T34: 1050 | U34: 1050 | V34: 1050 | W34: 1050 | X34: 1050 | Y34: 1050 | Z34: 1050 | AA34: 1050 | AB34: 1050 | AC34: 1050 | AD34: 1050 | AE34: 1050 | AF34: 1050 | AG34: 1050 | AH34: 1050 | AJ34: =SUM(E34:AI34)
A35: =A34+1 | B35: João Sérgio Silva Santos | E35: 3200 | F35: 3200 | G35: 3200 | H35: 3200 | I35: 3200 | J35: 3200 | K35: 3200 | L35: 3200 | M35: 3200 | N35: 3200 | O35: 3200 | P35: 3200 | Q35: 3200 | R35: 3200 | S35: 3200 | T35: 3200 | U35: 3200 | V35: 3200 | W35: 3200 | X35: 3200 | Y35: 3200 | Z35: 3200 | AJ35: =SUM(E35:AI35)
A36: =A35+1 | B36: Liseane Padilha Thives | E36: 3000 | AJ36: =SUM(E36:AI36)
A37: =A36+1 | B37: Luiza Ana Vendramin | E37: 1625 | F37: 1625 | G37: 1625 | H37: 1625 | I37: 1625 | J37: 1625 | K37: 1625 | AJ37: =SUM(E37:AI37)
A38: =A37+1 | B38: Rafael Augusto Dos Reis Higashi | E38: 3000 | AJ38: =SUM(E38:AI38)
A39: =A38+1 | B39: Roberto Caldas De Andrade Pinto | E39: 3000 | AJ39: =SUM(E39:AI39)
A40: =A39+1 | B40: Stephanie Thiesen | E40: 3000 | AJ40: =SUM(E40:AI40)
...

Sheet Prodesp
A1: N˚ | B1: Receita | D1: Até mai/26 | E1: 46174 | F1: 46204 | G1: 46235 | H1: 46266 | I1: 46296 | J1: 46327 | K1: 46357 | L1: 46388 | M1: 46419 | N1: 46447 | O1: 46478 | P1: Totais
A2: 1 | B2: Parcelas | D2: =E93 | E2: =1499855+1499855 | F2: 0 | G2: 1499855 | H2: 0 | I2: 0 | J2: 2249783 | K2: 0 | L2: 0 | M2: 2249783 | N2: 0 | O2: 749925 | P2: =SUM(D2:O2)
A3: N˚ | B3: Despesas | E3: =E1 | F3: =F1 | G3: =G1 | H3: =H1 | I3: =I1 | J3: =J1 | K3: =K1 | L3: =L1 | ... O3: =O1 | P3: Totais
A4: 1 | B4: Alberto Hauch Martinho | E4: =3173.83 | F4: =3173.83 | P4: =SUM(E4:O4)
A5: =A4+1 | B5: Alyne Zelinda de Barros | E5: =3548.24 | F5: =3548.24 | P5: =SUM(E5:O5)
A6: =A5+1 | B6: Davyd Carlos Martins | E6: =7652.5+797.57 | F6: =7652.5+797.57 | P6: =SUM(E6:O6)
A7: =A6+1 | B7: Débora Cristina Siridakis Correa | E7: =4813.76+288.83 | F7: =4813.76+288.83 | P7: =SUM(E7:O7)
A8: =A7+1 | B8: Gabriel da Cunha Lima | E8: =3721.04 | F8: =3721.04 | P8: =SUM(E8:O8)
A9: =A8+1 | B9: Graziane da Rocha Silveira | E9: =4297.8+257.87 | F9: =4297.8+257.87 | P9: =SUM(E9:O9)
A10: =A9+1 | B10: Inês Peglow | E10: =3907.09+801.71+423.79 | F10: =3907.09+801.71+423.79 | P10: =SUM(E10:O10)
A11: =A10+1 | B11: Karin Cristina Amorim | E11: =3597.65+431.72 | F11: =3597.65+431.72 | P11: =SUM(E11:O11)
A12: =A11+1 | B12: Lara Caldeira de Andrade e Silva | E12: =3907.09+234.43 | F12: =3907.09+234.43 | P12: =SUM(E12:O12)
A13: =A12+1 | B13: Lisiane do Carmo Nascimento de Oliveira Bispo | E13: =2606.08 | F13: =2606.08 | P13: =SUM(E13:O13)
A14: =A13+1 | B14: Mara Regina Bernardini | E14: =4626.83+694.02 | F14: =4626.83+694.02 | P14: =SUM(E14:O14)
A15: =A14+1 | B15: Marcos Antonio Braga | E15: =3548.24+638.68 | F15: =3548.24+638.68 | P15: =SUM(E15:O15)
A16: =A15+1 | B16: Marta Cristiani de Avila Rosa | E16: =3907.09+351.64 | F16: =3907.09+351.64 | P16: =SUM(E16:O16)
A17: =A16+1 | B17: Pedro Marques Abdo | E17: =3943.75+236.62 | F17: =3943.75+236.62 | P17: =SUM(E17:O17)
A18: =A17+1 | B18: Renilda de Quadros | E18: =4022.64+603.4 | F18: =4022.64+603.4 | P18: =SUM(E18:O18)
A19: =A18+1 | B19: Rithyelen Aliny da Silveira | E19: =3907.09+351.64 | F19: =3907.09+351.64 | P19: =SUM(E19:O19)
A20: =A19+1 | B20: Thiago de Almeida Rebollo | E20: 3550.24 | F20: 3551.24 | P20: =SUM(E20:O20)
A21: =A20+1 | B21: Alexandre Garcez Nunes | E21: =12180.93+730.88 | F21: =12180.93+730.88 | P21: =SUM(E21:O21)
A22: =A21+1 | B22: Bruno Maluche Neto | E22: =(19765.28+4743.67)*$Q$22 | F22: =(19765.28+4743.67)*$Q$22 | P22: =SUM(E22:O22) | Q22: =1-0.2574
A23: =A22+1 | B23: Fernanda Miranda | E23: =10052.21+904.7 | F23: =10052.21+904.7 | P23: =SUM(E23:O23)
A24: =A23+1 | B24: Giseli de Sousa | E24: =13593.2+1223.39 | F24: =13593.2+1223.39 | P24: =SUM(E24:O24)
A25: =A24+1 | B25: Joao Gabriel Crema | E25: =13592.7+2038.9 | F25: =13592.7+2038.9 | P25: =SUM(E25:O25)
A26: =A25+1 | B26: Josivan Laskoski | E26: =17670.52+2120.46 | F26: =17670.52+2120.46 | P26: =SUM(E26:O26)
A27: =A26+1 | B27: Marcelo Maciel Pereira | E27: =(11583.15+2779.96)*$Q$27 | F27: =(11583.15+2779.96)*$Q$27 | P27: =SUM(E27:O27) | Q27: =1-0.7862
A28: =A27+1 | B28: Morgana Leite | E28: =5994.65+539.52 | F28: =5994.65+539.52 | P28: =SUM(E28:O28)
A29: =A28+1 | B29: Rafael Berretta | E29: =5341.55+480.74 | F29: =5341.55+480.74 | P29: =SUM(E29:O29)
A30: =A29+1 | B30: Thaysa Momm Bastos | E30: =(6794.33+407.66)*$Q$30 | F30: =(6794.33+407.66)*$Q$30 | P30: =SUM(E30:O30) | Q30: =1-0.8144
A31: =A30+1 | B31: Alexandre Gonçalves | E31: =6153.88+369.23 | F31: =6153.88+369.23 | P31: =SUM(E31:O31)
A32: =A31+1 | B32: Aline Martins de Souza | E32: =5335.31+320.12 | F32: =5335.31+320.12 | P32: =SUM(E32:O32)
A33: =A32+1 | B33: Daniel Vieira Machado | E33: =12893.4 | F33: =12893.4 | P33: =SUM(E33:O33)
A34: =A33+1 | B34: Danilo Franklin Leite Lopes | E34: =7551.52 | F34: =7551.52 | P34: =SUM(E34:O34)
A35: =A34+1 | B35: Débora Machado Gonçalves | E35: =5635.44 | F35: =5635.44 | P35: =SUM(E35:O35)
A36: =A35+1 | B36: Deucélia Eva Pedroso | E36: =14406.21+864.37 | F36: =14406.21+864.37 | P36: =SUM(E36:O36)
A37: =A36+1 | B37: Eder Tagveira dos Santos | E37: 10500 | F37: 10500 | P37: =SUM(E37:O37)
A38: =A37+1 | B38: Elizabeth Ventura da Silva | E38: =4615.4+553.85 | F38: =4615.4+553.85 | P38: =SUM(E38:O38)
A39: =A38+1 | B39: Érika Cavalcante de Souza Tartari | E39: =6566.54 | F39: =6566.54 | P39: =SUM(E39:O39)
A40: =A39+1 | B40: Gabriel Domingos Adriano | E40: =6019.33 | F40: =6019.33 | P40: =SUM(E40:O40)
...

Sheet DER-MG
A1: N˚ | B1: Receita | D1: Até mai/26 | E1: 46174 | F1: 46204 | G1: 46235 | H1: 46266 | I1: 46296 | J1: 46327 | K1: 46357 | L1: 46388 | M1: 46419 | N1: 46447 | O1: Totais
A2: 1 | B2: Parcelas | D2: =E45 | E2: =400462+794997.15+520629 | F2: 0 | G2: 390715 | H2: 0 | I2: 404706 | J2: 0 | K2: 374383 | L2: 0 | M2: 122341 | N2: 0 | O2: =SUM(D2:N2)
A3: N˚ | B3: Despesas | E3: =E1 | F3: =F1 | G3: =G1 | H3: =H1 | I3: =I1 | J3: =J1 | K3: =K1 | L3: =L1 | ... N3: =N1 | O3: Totais
A4: 1 | B4: Adam Pereira Bidiaki | E4: 7305.2 | F4: 7305.2 | G4: 7305.2 | H4: 7305.2 | I4: 7305.2 | J4: 7305.2 | K4: 7305.2 | L4: 7305.2 | M4: 7305.2 | N4: 7305.2 | O4: =SUM(E4:N4)
A5: =A4+1 | B5: Alcyr Spindola Filho | E5: 4377.69 | F5: 4377.69 | G5: 4377.69 | H5: 4377.69 | I5: 4377.69 | J5: 4377.69 | K5: 4377.69 | L5: 4377.69 | M5: 4377.69 | N5: 4377.69 | O5: =SUM(E5:N5)
A6: =A5+1 | B6: Elvis Fagundes Lisboa Junior | E6: 4696.2 | F6: 4696.2 | G6: 4696.2 | H6: 4696.2 | I6: 4696.2 | J6: 4696.2 | K6: 4696.2 | L6: 4696.2 | M6: 4696.2 | N6: 4696.2 | O6: =SUM(E6:N6)
A7: =A6+1 | B7: Emanuel Espíndola | E7: =12900.99+1548.12 | F7: =12900.99+1548.12 | O7: =SUM(E7:N7)
A8: =A7+1 | B8: Kennildo Bastos Gonçalves | E8: 8348.8 | F8: 8348.8 | G8: 8348.8 | H8: 8348.8 | I8: 8348.8 | J8: 8348.8 | K8: 8348.8 | L8: 8348.8 | M8: 8348.8 | N8: 8348.8 | O8: =SUM(E8:N8)
A9: =A8+1 | B9: Keven Dantas da Silva | E9: 3861.32 | F9: 3861.32 | G9: 3861.32 | H9: 3861.32 | I9: 3861.32 | J9: 3861.32 | K9: 3861.32 | L9: 3861.32 | M9: 3861.32 | N9: 3861.32 | O9: =SUM(E9:N9)
A10: =A9+1 | B10: Pâmela Andressa Lunelli | E10: 6261.6 | F10: 6261.6 | G10: 6261.6 | H10: 6261.6 | I10: 6261.6 | J10: 6261.6 | K10: 6261.6 | L10: 6261.6 | M10: 6261.6 | N10: 6261.6 | O10: =SUM(E10:N10)
A11: =A10+1 | B11: Encargos s/pessoal contratado | E11: =SUM(E4:E10)*0.85 | F11: =SUM(F4:F10)*0.85 | G11: =SUM(G4:G10)*0.85 | H11: =SUM(H4:H10)*0.85 | I11: =SUM(I4:I10)*0.85 | J11: =SUM(J4:J10)*0.85 | K11: =SUM(K4:K10)*0.85 | L11: =SUM(L4:L10)*0.85 | ... N11: =SUM(N4:N10)*0.85 | O11: =SUM(E11:N11)
A12: =A11+1 | B12: Alexis Camilo Pantoja Pantoja | E12: 3200 | F12: 3200 | G12: 3200 | H12: 3200 | I12: 3200 | J12: 3200 | K12: 3200 | L12: 3200 | M12: 3200 | N12: 3200 | O12: =SUM(E12:N12)
A13: =A12+1 | B13: Amably Cristina Platen | E13: 4850 | F13: 4850 | G13: 4850 | O13: =SUM(E13:N13)
A14: =A13+1 | B14: Angelo De Bortoli Sarto | E14: 1050 | F14: 1050 | G14: 1050 | H14: 1050 | I14: 1050 | J14: 1050 | K14: 1050 | L14: 1050 | O14: =SUM(E14:N14)
A15: =A14+1 | B15: Anita Bohme Behar | E15: 1050 | F15: 1050 | G15: 1050 | H15: 1050 | I15: 1050 | J15: 1050 | K15: 1050 | L15: 1050 | O15: =SUM(E15:N15)
A16: =A15+1 | B16: Catharina Vogel de Carvalho | E16: 1050 | F16: 1050 | G16: 1050 | O16: =SUM(E16:N16)
A17: =A16+1 | B17: Djonathan Willian Schafer | E17: 1050 | F17: 1050 | G17: 1050 | H17: 1050 | I17: 1050 | J17: 1050 | K17: 1050 | L17: 1050 | O17: =SUM(E17:N17)
A18: =A17+1 | B18: Douglas Cheffer | E18: 1050 | F18: 1050 | G18: 1050 | O18: =SUM(E18:N18)
A19: =A18+1 | B19: Felipe Tagliari de Oliveira | E19: 1050 | F19: 1050 | G19: 1050 | H19: 1050 | I19: 1050 | J19: 1050 | K19: 1050 | L19: 1050 | O19: =SUM(E19:N19)
A20: =A19+1 | B20: Gabriel Alves Abade | E20: 3200 | F20: 3200 | G20: 3200 | O20: =SUM(E20:N20)
A21: =A20+1 | B21: Heloisa Silveira Morimoto | E21: 1050 | F21: 1050 | G21: 1050 | O21: =SUM(E21:N21)
A22: =A21+1 | B22: João Pedro Darabas Cardoso | E22: 1050 | F22: 1050 | G22: 1050 | O22: =SUM(E22:N22)
A23: =A22+1 | B23: Luis Fernando Heisler Damazio | E23: 1050 | F23: 1050 | G23: 1050 | H23: 1050 | I23: 1050 | J23: 1050 | O23: =SUM(E23:N23)
A24: =A23+1 | B24: Mariana Souto dos Anjos | E24: 2200 | F24: 2200 | G24: 2200 | H24: 2200 | I24: 2200 | J24: 2200 | K24: 2200 | L24: 2200 | M24: 2200 | N24: 2200 | O24: =SUM(E24:N24)
A25: =A24+1 | B25: Marina Rodrigues Pavanati | E25: 1050 | F25: 1050 | G25: 1050 | H25: 1050 | I25: 1050 | J25: 1050 | K25: 1050 | L25: 1050 | O25: =SUM(E25:N25)
A26: =A25+1 | B26: Roberto Lima Guedes | E26: 3200 | F26: 3200 | G26: 3200 | O26: =SUM(E26:N26)
A27: =A26+1 | B27: Rufino Sérgio Panzo | E27: 1050 | F27: 1050 | G27: 1050 | H27: 1050 | I27: 1050 | J27: 1050 | K27: 1050 | O27: =SUM(E27:N27)
A28: =A27+1 | B28: Sander Alex Pereira | E28: 1050 | F28: 1050 | G28: 1050 | H28: 1050 | I28: 1050 | J28: 1050 | O28: =SUM(E28:N28)
A29: =A28+1 | B29: Simone Alleotti Tesser | E29: 1050 | F29: 1050 | G29: 1050 | H29: 1050 | I29: 1050 | J29: 1050 | K29: 1050 | L29: 1050 | M29: 1050 | N29: 1050 | O29: =SUM(E29:N29)
A30: =A29+1 | B30: Sofia Cunha Dalpiaz | E30: 1050 | F30: 1050 | G30: 1050 | O30: =SUM(E30:N30)
A31: =A30+1 | B31: Serviços de Terceiros | E31: 2500 | F31: 2500 | G31: 2500 | H31: 2500 | I31: 2500 | J31: 2500 | K31: 2500 | L31: 2500 | M31: 2500 | O31: =SUM(E31:N31)
A32: =A31+1 | B32: Passagens | E32: 6500 | F32: 6500 | G32: 6500 | H32: 6500 | I32: 6500 | J32: 6500 | K32: 6500 | L32: 6500 | M32: 6500 | O32: =SUM(E32:N32)
A33: =A32+1 | B33: Diárias | E33: 3500 | F33: 3500 | G33: 3500 | H33: 3500 | I33: 3500 | J33: 3500 | K33: 3500 | L33: 3500 | M33: 3500 | O33: =SUM(E33:N33)
A34: =A33+1 | B34: Materrial de Consumo | E34: 1000 | F34: 1000 | G34: 1000 | H34: 1000 | I34: 1000 | J34: 1000 | K34: 1000 | L34: 1000 | M34: 1000 | N34: 1000 | O34: =SUM(E34:N34)
E35: =SUM(E4:E34) | F35: =SUM(F4:F34) | G35: =SUM(G4:G34) | H35: =SUM(H4:H34) | I35: =SUM(I4:I34) | J35: =SUM(J4:J34) | K35: =SUM(K4:K34) | L35: =SUM(L4:L34) | ... N35: =SUM(N4:N34) | O35: =SUM(E35:N35)
A36: =A34+1 | B36: Fundação de Apoio | D36: 0.0825 | E36: =E2*$D$36 | F36: =F2*$D$36 | G36: =G2*$D$36 | H36: =H2*$D$36 | I36: =I2*$D$36 | J36: =J2*$D$36 | K36: =K2*$D$36 | L36: =L2*$D$36 | ... N36: =N2*$D$36 | O36: =SUM(E36:N36)
A37: =A36+1 | B37: Universidade Federal | D37: 0.07 | E37: =E2*$D$37 | F37: =F2*$D$37 | G37: =G2*$D$37 | H37: =H2*$D$37 | I37: =I2*$D$37 | J37: =J2*$D$37 | K37: =K2*$D$37 | L37: =L2*$D$37 | ... N37: =N2*$D$37 | O37: =SUM(E37:N37)
A38: subtotal2 | E38: =SUM(E36:E37) | F38: =SUM(F36:F37) | G38: =SUM(G36:G37) | H38: =SUM(H36:H37) | I38: =SUM(I36:I37) | J38: =SUM(J36:J37) | K38: =SUM(K36:K37) | L38: =SUM(L36:L37) | ... O38: =SUM(O36:O37)
A39: Total Despesas | E39: =E38+E35 | F39: =F38+F35 | G39: =G38+G35 | H39: =H38+H35 | I39: =I38+I35 | J39: =J38+J35 | K39: =K38+K35 | L39: =L38+L35 | ... O39: =O38+O35
A40: Saldos | D40: =H45 | E40: =D40+E2-E39 | F40: =E40+F2-F39 | G40: =F40+G2-G39 | H40: =G40+H2-H39 | I40: =H40+I2-I39 | J40: =I40+J2-J39 | K40: =J40+K2-K39 | L40: =K40+L2-L39 | ... N40: =M40+N2-N39 | O40: =D40+O2-D2-O39
...

Sheet Goias II
A1: N˚ | B1: Receita | D1: Até mai/26 | E1: 46174 | F1: 46204 | G1: 46235 | H1: 46266 | I1: 46296 | J1: 46327 | K1: 46357 | L1: 46388 | M1: 46419 | N1: Totais
A2: 1 | B2: Parcelas | D2: =E28 | E2: 138912 | F2: 744659 | G2: 0 | H2: 183961 | I2: 0 | J2: 557874 | K2: 0 | L2: 373913 | M2: =103900.8+25975.2 | N2: =SUM(D2:M2)
A3: N˚ | B3: Despesas | E3: =E1 | F3: =F1 | G3: =G1 | H3: =H1 | I3: =I1 | J3: =J1 | K3: =K1 | L3: =L1 | M3: =M1 | N3: Totais
A4: 1 | B4: Equipe a Contratar | E4: 3000 | F4: 12000 | G4: =F4 | H4: =G4 | I4: =H4 | J4: =I4 | K4: =J4 | L4: =K4 | M4: =L4 | N4: =SUM(E4:M4)
A5: =A4+1 | B5: Equipe a Contratar | E5: =E4 | F5: =F4 | G5: =G4 | H5: =H4 | I5: =I4 | J5: =J4 | K5: =K4 | L5: =L4 | M5: =M4 | N5: =SUM(E5:M5)
A6: =A5+1 | B6: Equipe a Contratar | E6: =E5 | F6: =F5 | G6: =G5 | H6: =H5 | I6: =I5 | J6: =J5 | K6: =K5 | L6: =L5 | M6: =M5 | N6: =SUM(E6:M6)
A7: =A6+1 | B7: Equipe a Contratar | E7: =E6 | F7: =F6 | G7: =G6 | H7: =H6 | I7: =I6 | J7: =J6 | K7: =K6 | L7: =L6 | M7: =M6 | N7: =SUM(E7:M7)
A8: =A7+1 | B8: Equipe a Contratar | E8: =E7 | F8: =F7 | G8: =G7 | H8: =H7 | I8: =I7 | J8: =J7 | K8: =K7 | L8: =L7 | M8: =M7 | N8: =SUM(E8:M8)
A9: =A8+1 | B9: Equipe a Contratar | E9: =E8 | F9: =F8 | G9: =G8 | H9: =H8 | I9: =I8 | J9: =J8 | K9: =K8 | L9: =L8 | M9: =M8 | N9: =SUM(E9:M9)
A10: =A9+1 | B10: Equipe a Contratar | E10: =E9 | F10: =F9 | G10: =G9 | H10: =H9 | I10: =I9 | J10: =J9 | K10: =K9 | L10: =L9 | M10: =M9 | N10: =SUM(E10:M10)
A11: =A10+1 | B11: Encargos s/pessoal contratado | E11: =SUM(E4:E10)*0.85 | F11: =SUM(F4:F10)*0.85 | G11: =SUM(G4:G10)*0.85 | H11: =SUM(H4:H10)*0.85 | I11: =SUM(I4:I10)*0.85 | J11: =SUM(J4:J10)*0.85 | K11: =SUM(K4:K10)*0.85 | L11: =SUM(L4:L10)*0.85 | M11: =SUM(M4:M10)*0.85 | N11: =SUM(E11:M11)
A12: =A11+1 | B12: Bolsistas | E12: 10000 | F12: 10000 | G12: 10000 | H12: 10000 | I12: 10000 | J12: 10000 | K12: 10000 | L12: 10000 | M12: 10000 | N12: =SUM(E12:M12)
A13: =A12+1 | B13: Bolsistas | E13: 10000 | F13: 10000 | G13: 10000 | H13: 10000 | I13: 10000 | J13: 10000 | K13: 10000 | L13: 10000 | M13: 10000 | N13: =SUM(E13:M13)
A14: =A13+1 | B14: Serviços de Terceiros | E14: 2500 | F14: 2500 | G14: 2500 | H14: 2500 | I14: 2500 | J14: 2500 | K14: 2500 | L14: 2500 | M14: 2500 | N14: =SUM(E14:M14)
A15: =A14+1 | B15: Passagens | E15: 6500 | F15: 6500 | G15: 6500 | H15: 6500 | I15: 6500 | J15: 6500 | K15: 6500 | L15: 6500 | M15: 6500 | N15: =SUM(E15:M15)
A16: =A15+1 | B16: Diárias | E16: 3500 | F16: 3500 | G16: 3500 | H16: 3500 | I16: 3500 | J16: 3500 | K16: 3500 | L16: 3500 | M16: 3500 | N16: =SUM(E16:M16)
A17: =A16+1 | B17: Materrial de Consumo | E17: 1000 | F17: 1000 | G17: 1000 | H17: 1000 | I17: 1000 | J17: 1000 | K17: 1000 | L17: 1000 | M17: 1000 | N17: =SUM(E17:M17)
E18: =SUM(E4:E17) | F18: =SUM(F4:F17) | G18: =SUM(G4:G17) | H18: =SUM(H4:H17) | I18: =SUM(I4:I17) | J18: =SUM(J4:J17) | K18: =SUM(K4:K17) | L18: =SUM(L4:L17) | M18: =SUM(M4:M17) | N18: =SUM(E18:M18)
A19: =A17+1 | B19: Fundação de Apoio | D19: 0.0825 | E19: =E2*$D$19 | F19: =F2*$D$19 | G19: =G2*$D$19 | H19: =H2*$D$19 | I19: =I2*$D$19 | J19: =J2*$D$19 | K19: =K2*$D$19 | L19: =L2*$D$19 | M19: =M2*$D$19 | N19: =SUM(E19:M19)
A20: =A19+1 | B20: Universidade Federal | D20: 0.07 | E20: =E2*$D$20 | F20: =F2*$D$20 | G20: =G2*$D$20 | H20: =H2*$D$20 | I20: =I2*$D$20 | J20: =J2*$D$20 | K20: =K2*$D$20 | L20: =L2*$D$20 | M20: =M2*$D$20 | N20: =SUM(E20:M20)
A21: subtotal2 | E21: =SUM(E19:E20) | F21: =SUM(F19:F20) | G21: =SUM(G19:G20) | H21: =SUM(H19:H20) | I21: =SUM(I19:I20) | J21: =SUM(J19:J20) | K21: =SUM(K19:K20) | L21: =SUM(L19:L20) | ... N21: =SUM(N19:N20)
A22: Total Despesas | E22: =E21+E18 | F22: =F21+F18 | G22: =G21+G18 | H22: =H21+H18 | I22: =I21+I18 | J22: =J21+J18 | K22: =K21+K18 | L22: =L21+L18 | ... N22: =N21+N18
A23: Saldos | D23: =H28 | E23: =D23+E2-E22 | F23: =E23+F2-F22 | G23: =F23+G2-G22 | H23: =G23+H2-H22 | I23: =H23+I2-I22 | J23: =I23+J2-J22 | K23: =J23+K2-K22 | L23: =K23+L2-L22 | M23: =L23+M2-M22 | N23: =D23+N2-D2-N22
A25: N˚ | B25: Rubricas | C25: Perc. | D25: Previsto | E25: Recebido | F25: A Receber | G25: Gasto | H25: Saldo | I25: A gastar | J25: Result. | L25: Inicio | M25: 46135
A26: 1 | B26: Aplicação em Fundos | C26: 0 | D26: 0 | E26: 0 | F26: 0 | G26: 0 | H26: 0 | I26: 0 | J26: =H26-I26 | L26: Duração | M26: 10 meses
A27: =A26+1 | B27: Custos do |Projeto | C27: =D27/22661520 | D27: 2129195 | E27: 0 | F27: =D27-E27 | G27: 0 | H27: =E27+G27 | I27: =-N22 | J27: =E27+F27+G27+I27 | L27: Fim | M27: 46440
B28: Totais | C28: =SUM(C27:C27) | D28: =SUM(D26:D27) | E28: =SUM(E26:E27) | F28: =SUM(F26:F27) | G28: =SUM(G26:G27) | H28: =SUM(H26:H27) | I28: =SUM(I26:I27) | J28: =SUM(J26:J27)

Sheet RUMO
A1: N˚ | B1: Receita | D1: Até mai/26 | E1: 46174 | F1: 46204 | G1: 46235 | H1: 46266 | I1: 46296 | J1: 46327 | K1: 46357 | L1: 46388 | M1: 46419 | N1: 46447 | O1: 46478 | P1: 46508 | Q1: 46539 | R1: 46569 | S1: 46600 | T1: 46631 | U1: 46661 | V1: 46692 | W1: Totais
A2: 1 | B2: Parcelas | D2: =E29 | E2: 176245.81 | F2: 208190.02 | G2: 229943.52 | H2: 218323.89 | I2: 224912.34 | J2: 213292.71 | K2: 230722.16 | L2: 213292.71 | M2: 213292.71 | N2: 224912.34 | O2: 213292.71 | P2: 169438.58 | Q2: 181058.21 | R2: 169438.58 | S2: 171815.44 | T2: 130477.8 | U2: 142097.42 | V2: 0 | W2: =SUM(D2:V2)
A3: N˚ | B3: Despesas | D3: % salário | E3: =E1 | F3: =F1 | G3: =G1 | H3: =H1 | I3: =I1 | J3: =J1 | K3: =K1 | L3: =L1 | ... V3: =V1 | W3: Totais
A4: 1 | B4: Adriane Merten | D4: 1 | E4: =(8297.73+497.86)*$D$4 | F4: =(8297.73+497.86)*$D$4 | G4: =(8297.73+497.86)*$D$4 | H4: =(8297.73+497.86)*$D$4 | I4: =(8297.73+497.86)*$D$4 | J4: =(8297.73+497.86)*$D$4 | K4: =(8297.73+497.86)*$D$4 | L4: =(8297.73+497.86)*$D$4 | M4: =(8297.73+497.86)*$D$4 | N4: =((8297.73+497.86)*$D$4)*1.05 | O4: =((8297.73+497.86)*$D$4)*1.05 | P4: =((8297.73+497.86)*$D$4)*1.05 | Q4: =((8297.73+497.86)*$D$4)*1.05 | R4: =((8297.73+497.86)*$D$4)*1.05 | S4: =((8297.73+497.86)*$D$4)*1.05 | T4: =((8297.73+497.86)*$D$4)*1.05 | U4: =((8297.73+497.86)*$D$4)*1.05 | W4: =SUM(E4:V4)
A5: =A4+1 | B5: André Ricardo Hadlich | D5: 0.5347 | E5: =(16009.77+2881.76)*$D$5 | F5: =(16009.77+2881.76)*$D$5 | G5: =(16009.77+2881.76)*$D$5 | H5: =(16009.77+2881.76)*$D$5 | I5: =(16009.77+2881.76)*$D$5 | J5: =(16009.77+2881.76)*$D$5 | K5: =(16009.77+2881.76)*$D$5 | L5: =(16009.77+2881.76)*$D$5 | M5: =(16009.77+2881.76)*$D$5 | N5: =((16009.77+2881.76)*$D$5)*1.05 | O5: =((16009.77+2881.76)*$D$5)*1.05 | P5: =((16009.77+2881.76)*$D$5)*1.05 | Q5: =((16009.77+2881.76)*$D$5)*1.05 | R5: =((16009.77+2881.76)*$D$5)*1.05 | S5: =((16009.77+2881.76)*$D$5)*1.05 | T5: =((16009.77+2881.76)*$D$5)*1.05 | U5: =((16009.77+2881.76)*$D$5)*1.05 | W5: =SUM(E5:V5)
A6: =A5+1 | B6: Bruno Maluche Neto | D6: 0.2574 | E6: =(19765.28+4743.67)*$D$6 | F6: =(19765.28+4743.67)*$D$6 | G6: =(19765.28+4743.67)*$D$6 | H6: =(19765.28+4743.67)*$D$6 | I6: =(19765.28+4743.67)*$D$6 | J6: =(19765.28+4743.67)*$D$6 | K6: =(19765.28+4743.67)*$D$6 | L6: =(19765.28+4743.67)*$D$6 | M6: =(19765.28+4743.67)*$D$6 | N6: =((19765.28+4743.67)*$D$6)*1.05 | O6: =((19765.28+4743.67)*$D$6)*1.05 | P6: =((19765.28+4743.67)*$D$6)*1.05 | Q6: =((19765.28+4743.67)*$D$6)*1.05 | R6: =((19765.28+4743.67)*$D$6)*1.05 | S6: =((19765.28+4743.67)*$D$6)*1.05 | T6: =((19765.28+4743.67)*$D$6)*1.05 | U6: =((19765.28+4743.67)*$D$6)*1.05 | W6: =SUM(E6:V6)
A7: =A6+1 | B7: Daniela Vogel | D7: 0.4584 | E7: =(8390.54+1510.3)*$D$7 | F7: =(8390.54+1510.3)*$D$7 | G7: =(8390.54+1510.3)*$D$7 | H7: =(8390.54+1510.3)*$D$7 | I7: =(8390.54+1510.3)*$D$7 | J7: =(8390.54+1510.3)*$D$7 | K7: =(8390.54+1510.3)*$D$7 | L7: =(8390.54+1510.3)*$D$7 | M7: =(8390.54+1510.3)*$D$7 | N7: =((8390.54+1510.3)*$D$7)*1.05 | O7: =((8390.54+1510.3)*$D$7)*1.05 | P7: =((8390.54+1510.3)*$D$7)*1.05 | Q7: =((8390.54+1510.3)*$D$7)*1.05 | R7: =((8390.54+1510.3)*$D$7)*1.05 | S7: =((8390.54+1510.3)*$D$7)*1.05 | T7: =((8390.54+1510.3)*$D$7)*1.05 | U7: =((8390.54+1510.3)*$D$7)*1.05 | W7: =SUM(E7:V7)
A8: =A7+1 | B8: Gabriel Lisboa Bordin | D8: 1 | E8: =5610*$D$8 | F8: =5610*$D$8 | G8: =5610*$D$8 | H8: =5610*$D$8 | I8: =5610*$D$8 | J8: =5610*$D$8 | K8: =5610*$D$8 | L8: =5610*$D$8 | M8: =5610*$D$8 | N8: =(5610*$D$8)*1.05 | O8: =(5610*$D$8)*1.05 | P8: =(5610*$D$8)*1.05 | Q8: =(5610*$D$8)*1.05 | R8: =(5610*$D$8)*1.05 | S8: =(5610*$D$8)*1.05 | T8: =(5610*$D$8)*1.05 | U8: =(5610*$D$8)*1.05 | W8: =SUM(E8:V8)
A9: =A8+1 | B9: Marcelo Maciel Pereira | D9: 0.7862 | E9: =(11583.15+2779.96)*$D$9 | F9: =(11583.15+2779.96)*$D$9 | G9: =(11583.15+2779.96)*$D$9 | H9: =(11583.15+2779.96)*$D$9 | I9: =(11583.15+2779.96)*$D$9 | J9: =(11583.15+2779.96)*$D$9 | K9: =(11583.15+2779.96)*$D$9 | L9: =(11583.15+2779.96)*$D$9 | M9: =(11583.15+2779.96)*$D$9 | N9: =((11583.15+2779.96)*$D$9)*1.05 | O9: =((11583.15+2779.96)*$D$9)*1.05 | P9: =((11583.15+2779.96)*$D$9)*1.05 | Q9: =((11583.15+2779.96)*$D$9)*1.05 | R9: =((11583.15+2779.96)*$D$9)*1.05 | S9: =((11583.15+2779.96)*$D$9)*1.05 | T9: =((11583.15+2779.96)*$D$9)*1.05 | U9: =((11583.15+2779.96)*$D$9)*1.05 | W9: =SUM(E9:V9)
A10: =A9+1 | B10: Thaísa Momm Bastos | D10: 0.8144 | E10: =(6794.33+407.66)*$D$10 | F10: =(6794.33+407.66)*$D$10 | G10: =(6794.33+407.66)*$D$10 | H10: =(6794.33+407.66)*$D$10 | I10: =(6794.33+407.66)*$D$10 | J10: =(6794.33+407.66)*$D$10 | K10: =(6794.33+407.66)*$D$10 | L10: =(6794.33+407.66)*$D$10 | M10: =(6794.33+407.66)*$D$10 | N10: =((6794.33+407.66)*$D$10)*1.05 | O10: =((6794.33+407.66)*$D$10)*1.05 | P10: =((6794.33+407.66)*$D$10)*1.05 | Q10: =((6794.33+407.66)*$D$10)*1.05 | R10: =((6794.33+407.66)*$D$10)*1.05 | S10: =((6794.33+407.66)*$D$10)*1.05 | T10: =((6794.33+407.66)*$D$10)*1.05 | U10: =((6794.33+407.66)*$D$10)*1.05 | W10: =SUM(E10:V10)
A11: =A10+1 | B11: Encargos s/pessoal contratado | E11: =SUM(E4:E10)*0.85 | F11: =SUM(F4:F10)*0.85 | G11: =SUM(G4:G10)*0.85 | H11: =SUM(H4:H10)*0.85 | I11: =SUM(I4:I10)*0.85 | J11: =SUM(J4:J10)*0.85 | K11: =SUM(K4:K10)*0.85 | L11: =SUM(L4:L10)*0.85 | ... V11: =SUM(V4:V10)*0.85 | W11: =SUM(E11:V11)
A12: =A11+1 | B12: Arthur Rosa dos Santos | E12: 1050 | F12: 1050 | G12: 1050 | H12: 1050 | W12: =SUM(E12:V12)
A13: =A12+1 | B13: Helena Schiemann Maia | E13: 1050 | F13: 1050 | W13: =SUM(E13:V13)
A14: =A13+1 | B14: Henrique Rafael Sousa de Oliveira | E14: 1050 | F14: 1050 | G14: 1050 | H14: 1050 | W14: =SUM(E14:V14)
A15: =A14+1 | B15: Serviços de Terceiros | E15: 3500 | F15: 3500 | G15: 3500 | H15: 3500 | I15: 3500 | J15: 3500 | K15: 3500 | L15: 3500 | M15: 3500 | N15: 3500 | O15: 3500 | P15: 3500 | Q15: 3500 | R15: 3500 | S15: 3500 | T15: 3500 | U15: 3500 | W15: =SUM(E15:V15)
A16: =A15+1 | B16: Passagens | E16: 4000 | F16: 4000 | G16: 4000 | H16: 4000 | I16: 4000 | J16: 4000 | K16: 4000 | L16: 4000 | M16: 4000 | N16: 4000 | O16: 4000 | P16: 4000 | Q16: 4000 | R16: 4000 | S16: 4000 | T16: 4000 | U16: 4000 | W16: =SUM(E16:V16)
A17: =A16+1 | B17: Diárias | E17: =15300/18 | F17: =15300/18 | G17: =15300/18 | H17: =15300/18 | I17: =15300/18 | J17: =15300/18 | K17: =15300/18 | L17: =15300/18 | ... U17: =15300/18 | W17: =SUM(E17:V17)
A18: =A17+1 | B18: Materrial de Consumo | E18: =41400/18 | F18: =41400/18 | G18: =41400/18 | H18: =41400/18 | I18: =41400/18 | J18: =41400/18 | K18: =41400/18 | L18: =41400/18 | ... U18: =41400/18 | W18: =SUM(E18:V18)
E19: =SUM(E4:E18) | F19: =SUM(F4:F18) | G19: =SUM(G4:G18) | H19: =SUM(H4:H18) | I19: =SUM(I4:I18) | J19: =SUM(J4:J18) | K19: =SUM(K4:K18) | L19: =SUM(L4:L18) | ... W19: =SUM(W4:W18)
A20: =A18+1 | B20: Fundação de Apoio | D20: 0.081726355 | E20: =E2*$D$20 | F20: =F2*$D$20 | G20: =G2*$D$20 | H20: =H2*$D$20 | I20: =I2*$D$20 | J20: =J2*$D$20 | K20: =K2*$D$20 | L20: =L2*$D$20 | ... V20: =V2*$D$20 | W20: =SUM(E20:V20)
A21: =A20+1 | B21: Universidade Federal | D21: 0.083479422 | E21: =E2*$D$21 | F21: =F2*$D$21 | G21: =G2*$D$21 | H21: =H2*$D$21 | I21: =I2*$D$21 | J21: =J2*$D$21 | K21: =K2*$D$21 | L21: =L2*$D$21 | ... V21: =V2*$D$21 | W21: =SUM(E21:V21)
A22: subtotal2 | E22: =SUM(E20:E21) | F22: =SUM(F20:F21) | G22: =SUM(G20:G21) | H22: =SUM(H20:H21) | I22: =SUM(I20:I21) | J22: =SUM(J20:J21) | K22: =SUM(K20:K21) | L22: =SUM(L20:L21) | ... W22: =SUM(W20:W21)
A23: Total Despesas | E23: =E22+E19 | F23: =F22+F19 | G23: =G22+G19 | H23: =H22+H19 | I23: =I22+I19 | J23: =J22+J19 | K23: =K22+K19 | L23: =L22+L19 | ... V23: =V22+V19 | W23: =SUM(E23:V23)
A24: Saldos | D24: =H29 | E24: =D24+E2-E23 | F24: =E24+F2-F23 | G24: =F24+G2-G23 | H24: =G24+H2-H23 | I24: =H24+I2-I23 | J24: =I24+J2-J23 | K24: =J24+K2-K23 | L24: =K24+L2-L23 | ... V24: =U24+V2-V23 | W24: =D24+W2-D2-W23
A26: N˚ | B26: Rubricas | C26: Perc. | D26: Previsto | E26: Recebido | F26: A Receber | G26: Gasto | H26: Saldo | I26: A gastar | J26: Result. | L26: Inicio | M26: 46148
A27: 1 | B27: Aplicação em Fundos | C27: 0 | D27: 0 | E27: 0 | F27: 0 | G27: 0 | H27: 0 | I27: 0 | J27: =H27-I27 | L27: Duração | M27: 18 meses
A28: =A27+1 | B28: Custos do |Projeto | C28: =D28/22661520 | D28: 3484532.1 | E28: 153785.19 | F28: =D28-E28 | G28: =48676.54-153785 | H28: =E28+G28 | I28: =-W23 | J28: =E28+F28+G28+I28 | L28: Fim | M28: 46697
B29: Totais | C29: =SUM(C28:C28) | D29: =SUM(D27:D28) | E29: =SUM(E27:E28) | F29: =SUM(F27:F28) | G29: =SUM(G27:G28) | H29: =SUM(H27:H28) | I29: =SUM(I27:I28) | J29: =SUM(J27:J28)
D31: =D28*7%

Sheet Goiás
A1: N˚ | B1: Receita | C1: Até mai/26 | D1: 46174 | E1: 46204 | F1: 46235 | G1: Totais
A2: 1 | B2: Parcelas | C2: =E36 | D2: 386470 | E2: 0 | F2: 177017 | G2: =SUM(C2:F2)
A3: N˚ | B3: Despesas | D3: =D1 | E3: =E1 | F3: =F1 | G3: Totais
A4: 1 | B4: Lucas Zomignani Oliveira | D4: 8196.43 | E4: 8196.43 | F4: 8196.43 | G4: =SUM(D4:F4)
A5: =A4+1 | B5: Encargos Trabalhistas | D5: =SUM(D4:D4)*0.85 | E5: =SUM(E4:E4)*0.85 | F5: =SUM(F4:F4)*0.85 | G5: =SUM(D5:F5)
A6: =A5+1 | B6: Fernando de Melo e Silva | D6: =77285.88/6 | E6: =77285.88/6 | G6: =SUM(D6:F6)
A7: =A6+1 | B7: Flavia Nascimento Pureza Mello | D7: 9000 | G7: =SUM(D7:F7)
A8: =A7+1 | B8: Encargos s/RPA - 20% | D8: =SUM(D6:D7)*0.2 | E8: =SUM(E6:E7)*0.2 | F8: =SUM(F6:F7)*0.2 | G8: =SUM(D8:F8)
A9: =A8+1 | B9: Danton Henrique Santos D'Almeida | D9: 3200 | E9: 3200 | F9: 3200 | G9: =SUM(D9:F9)
A10: =A9+1 | B10: Gabriel Martins Folador | D10: 1050 | E10: 1050 | F10: 1050 | G10: =SUM(D10:F10)
A11: =A10+1 | B11: Kamilly Alana Vendramini | D11: 1050 | E11: 1050 | F11: 1050 | G11: =SUM(D11:F11)
A12: =A11+1 | B12: Natalia Sagaz | D12: 2200 | E12: 2200 | F12: 2200 | G12: =SUM(D12:F12)
A13: =A12+1 | B13: Nathalia Julia Moura | D13: 1050 | E13: 1050 | F13: 1050 | G13: =SUM(D13:F13)
A14: =A13+1 | B14: Rian Fabiano Venezio | D14: 2200 | E14: 2200 | F14: 2200 | G14: =SUM(D14:F14)
A15: =A14+1 | B15: Serviços de Terceiros | D15: 3000 | E15: 3000 | F15: 3000 | G15: =SUM(D15:F15)
A16: =A15+1 | B16: Passagens e Locomoções | D16: 5000 | E16: 5000 | F16: 5000 | G16: =SUM(D16:F16)
A17: =A16+1 | B17: Diárias | D17: 2500 | E17: 2500 | F17: 2500 | G17: =SUM(D17:F17)
A18: =A17+1 | B18: Material de Consumo | D18: 3500 | E18: 3500 | F18: 3500 | G18: =SUM(D18:F18)
A19: subtotal | D19: =SUM(D4:D18) | E19: =SUM(E4:E18) | F19: =SUM(F4:F18) | G19: =SUM(G4:G18)
A20: =A18+1 | B20: FAPEU | C20: 0.1 | D20: =D2*$C$20 | E20: =E2*$C$20 | F20: =F2*$C$20 | G20: =SUM(D20:F20)
A21: =A20+1 | B21: UFSC | C21: 0.07 | D21: =D2*$C$21 | E21: =E2*$C$21 | F21: =F2*$C$21 | G21: =SUM(D21:F21)
A22: subtotal | D22: =SUM(D20:D21) | E22: =SUM(E20:E21) | F22: =SUM(F20:F21) | G22: =SUM(G20:G21)
A23: Total Despesas | D23: =D22+D19 | E23: =E22+E19 | F23: =F22+F19 | G23: =G22+G19
A24: Saldos | C24: =H36 | D24: =C24+D2-D23 | E24: =D24+E2-E23 | F24: =E24+F2-F23 | G24: =G2+C24-C2-G23
A26: N˚ | B26: Rubricas | C26: Perc. | D26: Previsto | E26: Recebido | F26: A Receber | G26: Gasto | H26: Saldo | I26: A gastar | J26: Result. | L26: Inicio | M26: 45863
A27: 1 | B27: Aplicação em Fundos | C27: 0 | D27: 0 | E27: 0 | F27: 0 | G27: 0 | H27: 9645 | I27: 0 | J27: =H27-I27 | L27: término | M27: 46167
A28: =A27+1 | B28: Equipe Técnica | C28: =D28/2553140 | D28: 1357928.3 | E28: =1989653*C28 | F28: =D28-E28 | G28: 0 | H28: =E28+G28 | I28: =-SUM(G4:G14) | J28: =E28+F28+G28+I28 | L28: Execução | M28: 10 meses
A29: =A28+1 | B29: Passagens / Locomoção | C29: =D29/2553140 | D29: 44800 | E29: =1989653*C29 | F29: =D29-E29 | G29: 0 | H29: =E29+G29 | I29: =-G16 | J29: =E29+F29+G29+I29
A30: =A29+1 | B30: Diárias | C30: =D30/2553140 | D30: 21377.92 | E30: =1989653*C30 | F30: =D30-E30 | G30: 0 | H30: =E30+G30 | I30: =-G17 | J30: =E30+F30+G30+I30
A31: =A30+1 | B31: Serviços de Terceiros | C31: =D31/2553140 | D31: 570000 | E31: =1989653*C31 | F31: =D31-E31 | G31: 0 | H31: =E31+G31 | I31: =-G15 | J31: =E31+F31+G31+I31
A32: =A31+1 | B32: Material de Consumo | C32: =D32/2553140 | D32: 35000 | E32: =1989653*C32 | F32: =D32-E32 | G32: 0 | H32: =E32+G32 | I32: =-G18 | J32: =E32+F32+G32+I32
A33: =A32+1 | B33: Equipamentos | C33: =D33/2553140 | D33: 90000 | E33: =1989653*C33 | F33: =D33-E33 | G33: 0 | H33: =E33+G33 | I33: 0 | J33: =E33+F33+G33+I33
A34: =A33+1 | B34: UFSC | C34: =D34/2553140 | D34: 178719.8 | E34: =1989653*C34 | F34: =D34-E34 | G34: 0 | H34: =E34+G34 | I34: =-G21 | J34: =E34+F34+G34+I34
A35: =A34+1 | B35: Fundação | C35: =D35/2553140 | D35: 255314 | E35: =1989653*C35 | F35: =D35-E35 | G35: -1464282.9 | H35: =E35+G35 | I35: =-G20 | J35: =E35+F35+G35+I35
B36: Totais | C36: =SUM(C27:C35) | D36: =SUM(D27:D35) | E36: =SUM(E27:E35) | F36: =SUM(F27:F35) | G36: =SUM(G27:G35) | H36: =SUM(H27:H35) | I36: =SUM(I27:I35) | J36: =SUM(J27:J35)
J38: 240770
J39: =J38-J36

Sheet SAC BIM
A1: N˚ | B1: Receita | D1: Até mai/26 | E1: 46174 | F1: 46204 | G1: 46235 | H1: 46266 | I1: 46296 | J1: 46327 | K1: 46357 | L1: 46388 | M1: 46419 | N1: 46447 | O1: 46478 | P1: 46508 | Q1: 46539 | R1: 46569 | S1: 46600 | T1: 46631 | U1: 46661 | V1: 46692 | W1: 46722 | X1: 46753 | Y1: 46784 | Z1: 46813 | AA1: 46844 | AB1: 46874 | AC1: 46905 | AD1: 46935 | AE1: 46966 | AF1: 46997 | AG1: 47027 | AH1: 47058 | AI1: 47088 | AJ1: 47119 | AK1: 47150 | AL1: 47178 | AM1: 47209 | AN1: 47239 | AO1: 47270 | AP1: 47300 | AQ1: 47331 | AR1: 47362 | AS1: 47392 | AT1: 47423 | AU1: 47453 | AV1: 47484 | AW1: 47515 | AX1: 47543 | AY1: 47574 | AZ1: 47604 | BA1: 47635 | BB1: 47665 | BC1: 47696 | BD1: 47727 | BE1: 47757 | BF1: 47788 | BG1: 47818 | BH1: Totais
A2: 1 | B2: Parcelas | D2: =E136 | E2: 0 | F2: 0 | G2: 0 | H2: 0 | I2: 0 | J2: 4050411 | K2: 0 | L2: 0 | M2: 0 | N2: 3654500 | O2: 0 | P2: 0 | Q2: 0 | R2: 3525320 | S2: 0 | T2: 0 | U2: 0 | V2: 3482260 | W2: 0 | X2: 0 | Y2: 0 | Z2: 3482260 | AA2: 0 | AB2: 0 | AC2: 0 | AD2: 3482260 | AE2: 0 | AF2: 0 | AG2: 0 | AH2: 3482260 | AI2: 0 | AJ2: 0 | AK2: 0 | AL2: 3482260 | AM2: 0 | AN2: 0 | AO2: 0 | AP2: 3482260 | AQ2: 0 | AR2: 0 | AS2: 0 | AT2: 2555948 | AU2: 0 | AV2: 0 | AW2: 0 | AX2: 2555948 | AY2: 0 | AZ2: 0 | BA2: 0 | BB2: 3534567 | BC2: 0 | BD2: 0 | BE2: 0 | BF2: 0 | BG2: 0 | BH2: =SUM(D2:BG2)
A3: N˚ | B3: Despesas | E3: =E1 | F3: =F1 | G3: =G1 | H3: =H1 | I3: =I1 | J3: =J1 | K3: =K1 | L3: =L1 | ... BG3: =BG1 | BH3: Totais
A4: 1 | B4: Alana Vargas Magalhães | E4: 11709.19 | F4: 11709.19 | G4: 11709.19 | H4: 11709.19 | I4: 11709.19 | J4: 11709.19 | K4: 11709.19 | L4: 11709.19 | M4: 11709.19 | N4: =M4*1.05 | O4: =N4 | P4: =O4 | Q4: =P4 | R4: =Q4 | S4: =R4 | T4: =S4 | U4: =T4 | V4: =U4 | ... Y4: =X4 | Z4: =Y4*1.05 | AA4: =Z4 | AB4: =AA4 | AC4: =AB4 | AD4: =AC4 | AE4: =AD4 | AF4: =AE4 | AG4: =AF4 | AH4: =AG4 | ... AK4: =AJ4 | AL4: =AK4*1.05 | AM4: =AL4 | AN4: =AM4 | AO4: =AN4 | AP4: =AO4 | AQ4: =AP4 | AR4: =AQ4 | AS4: =AR4 | AT4: =AS4 | ... AW4: =AV4 | BH4: =SUM(E4:BG4)
